Workbook

Sheet Livestock Count
A1: State/UT | B1: Cattle | C1: Buffalo | D1: Sheep | E1: Goat | F1: Pig | G1: Total Eligible Animals
A2: Andaman & Nicobar Islands | B2: 36438 | C2: 3700 | D2: 5 | E2: 64761 | F2: 40488 | G2: =SUM(B2:F2) -> 145392
A3: Andhra Pradesh | B3: 4600087 | C3: 6219499 | D3: 17626971 | E3: 5522133 | F3: 91958 | G3: =SUM(B3:F3) -> 34060648
A4: Arunachal Pradesh | B4: 339221 | C4: 6379 | D4: 7345 | E4: 159740 | F4: 271463 | G4: =SUM(B4:F4) -> 784148
A5: Assam | B5: 10909239 | C5: 421715 | D5: 332100 | E5: 4315173 | F5: 2099000 | G5: =SUM(B5:F5) -> 18077227
A6: Bihar | B6: 15397980 | C6: 7719794 | D6: 213377 | E6: 12821216 | F6: 343434 | G6: =SUM(B6:F6) -> 36495801
A7: Chandigarh | B7: 13440 | C7: 12177 | D7: 0 | E7: 998 | F7: 138 | G7: =SUM(B7:F7) -> 26753
A8: Chhattisgarh | B8: 9983954 | C8: 1174722 | D8: 180229 | E8: 4005657 | F8: 526901 | G8: =SUM(B8:F8) -> 15871463
A9: Dadra & Nagar Haveli | B9: 39736 | C9: 997 | D9: 84 | E9: 7548 | F9: 0 | G9: =SUM(B9:F9) -> 48365
A10: Daman & Diu | B10: 1840 | C10: 374 | D10: 68 | E10: 987 | F10: 0 | G10: =SUM(B10:F10) -> 3269
A11: Delhi | B11: 86433 | C11: 162142 | D11: 932 | E11: 30470 | F11: 76346 | G11: =SUM(B11:F11) -> 356323
A12: Goa | B12: 60247 | C12: 27207 | D12: 8 | E12: 9446 | F12: 35480 | G12: =SUM(B12:F12) -> 132388
A13: Gujarat | B13: 9633637 | C13: 10543250 | D13: 1787263 | E13: 4867744 | F13: 658 | G13: =SUM(B13:F13) -> 26832552
... A37: West Bengal | B37: 19077916 | C37: 630921 | D37: 952886 | E37: 16279340 | F37: 540356 | G37: =SUM(B37:F37) -> 37481419

Sheet Assumptions
A1: Parameter | B1: Value | C1: Scientific Rationale / Source
A2: Calving Rate | B2: 0.55 | C2: Average national calving rate used by DAHD/NDDB planning models
A3: Female Calf % | B3: 0.45 | C3: Observed female calf ratio in bovines (~45–48%)
A4: Coverage % | B4: 0.95 | C4: Target programmatic coverage under NADCP/LHDCP
A5: Wastage % | B5: 0.05 | C5: Programmatic wastage during field vaccination
A6: Expiry % | B6: 0.03 | C6: Shelf-life expiry & batch residual loss
A7: Cold Chain Loss % | B7: 0.02 | C7: Cold-chain breakage & handling loss
A8: Buffer Stock % | B8: 0.1 | C8: Operational buffer stock for uninterrupted campaigns
A9: Campaign Clustering % | B9: 0.05 | C9: Clustering of campaigns / synchronized drives

Sheet Vaccine Parameters
A1: Vaccine | B1: Target Species | C1: Doses per Animal per Year
A2: FMD | B2: Cattle+Buffalo+Sheep+Goat+Pig | C2: 2
A3: Brucellosis | B3: Female Cattle+Buffalo | C3: 1
A4: PPR | B4: Sheep+Goat | C4: 1
A5: CSF | B5: Pig | C5: 1
A6: LSD | B6: Cattle | C6: 1

Sheet Demand Estimation
A1: State/UT | B1: Base Eligible Animals | C1: New Birth Eligible | D1: Adjusted Eligible (Coverage) | E1: Current Inventory (Editable) | F1: Annual Dose Requirement | G1: After Losses | H1: After Buffer & Campaign | I1: Monthly Demand | J1: Half-Yearly Demand | K1: Annual Demand
A2: ='Livestock Count'!A2 -> Andaman & Nicobar Islands | B2: ='Livestock Count'!G2 -> 145392 | C2: =B2*Assumptions!B2*Assumptions!B3 -> 35984.52 | D2: =(B2+C2)*Assumptions!B4 -> 172307.69 | E2: 0 | F2: =(D2-E2)*2 -> 344615.39 | G2: =F2*(1+Assumptions!B5+Assumptions!B6+Assumptions!B7) -> 379076.93 | H2: =G2*(1+Assumptions!B8+Assumptions!B9) -> 435938.47 | I2: =H2/12 -> 36328.205 | J2: =H2/2 -> 217969.23 | K2: =H2 -> 435938.47
A3: ='Livestock Count'!A3 -> Andhra Pradesh | B3: ='Livestock Count'!G3 -> 34060648 | C3: =B3*Assumptions!B2*Assumptions!B3 -> 8430010.4 | D3: =(B3+C3)*Assumptions!B4 -> 40366125 | E3: 0 | F3: =(D3-E3)*2 -> 80732251 | G3: =F3*(1+Assumptions!B5+Assumptions!B6+Assumptions!B7) -> 88805476 | H3: =G3*(1+Assumptions!B8+Assumptions!B9) -> 1.021263e+08 | I3: =H3/12 -> 8510524.8 | J3: =H3/2 -> 51063149 | K3: =H3 -> 1.021263e+08
A4: ='Livestock Count'!A4 -> Arunachal Pradesh | B4: ='Livestock Count'!G4 -> 784148 | C4: =B4*Assumptions!B2*Assumptions!B3 -> 194076.63 | D4: =(B4+C4)*Assumptions!B4 -> 929313.4 | E4: 0 | F4: =(D4-E4)*2 -> 1858626.8 | G4: =F4*(1+Assumptions!B5+Assumptions!B6+Assumptions!B7) -> 2044489.5 | H4: =G4*(1+Assumptions!B8+Assumptions!B9) -> 2351162.9 | I4: =H4/12 -> 195930.24 | J4: =H4/2 -> 1175581.4 | K4: =H4 -> 2351162.9
A5: ='Livestock Count'!A5 -> Assam | B5: ='Livestock Count'!G5 -> 18077227 | C5: =B5*Assumptions!B2*Assumptions!B3 -> 4474113.7 | D5: =(B5+C5)*Assumptions!B4 -> 21423774 | E5: 0 | F5: =(D5-E5)*2 -> 42847547 | G5: =F5*(1+Assumptions!B5+Assumptions!B6+Assumptions!B7) -> 47132302 | H5: =G5*(1+Assumptions!B8+Assumptions!B9) -> 54202147 | I5: =H5/12 -> 4516845.6 | J5: =H5/2 -> 27101074 | K5: =H5 -> 54202147
A6: ='Livestock Count'!A6 -> Bihar | B6: ='Livestock Count'!G6 -> 36495801 | C6: =B6*Assumptions!B2*Assumptions!B3 -> 9032710.7 | D6: =(B6+C6)*Assumptions!B4 -> 43252086 | E6: 0 | F6: =(D6-E6)*2 -> 86504172 | G6: =F6*(1+Assumptions!B5+Assumptions!B6+Assumptions!B7) -> 95154590 | H6: =G6*(1+Assumptions!B8+Assumptions!B9) -> 1.0942778e+08 | I6: =H6/12 -> 9118981.5 | J6: =H6/2 -> 54713889 | K6: =H6 -> 1.0942778e+08
A7: ='Livestock Count'!A7 -> Chandigarh | B7: ='Livestock Count'!G7 -> 26753 | C7: =B7*Assumptions!B2*Assumptions!B3 -> 6621.3675 | D7: =(B7+C7)*Assumptions!B4 -> 31705.649 | E7: 0 | F7: =(D7-E7)*2 -> 63411.298 | G7: =F7*(1+Assumptions!B5+Assumptions!B6+Assumptions!B7) -> 69752.428 | H7: =G7*(1+Assumptions!B8+Assumptions!B9) -> 80215.292 | I7: =H7/12 -> 6684.6077 | J7: =H7/2 -> 40107.646 | K7: =H7 -> 80215.292
A8: ='Livestock Count'!A8 -> Chhattisgarh | B8: ='Livestock Count'!G8 -> 15871463 | C8: =B8*Assumptions!B2*Assumptions!B3 -> 3928187.1 | D8: =(B8+C8)*Assumptions!B4 -> 18809668 | E8: 0 | F8: =(D8-E8)*2 -> 37619335 | G8: =F8*(1+Assumptions!B5+Assumptions!B6+Assumptions!B7) -> 41381269 | H8: =G8*(1+Assumptions!B8+Assumptions!B9) -> 47588459 | I8: =H8/12 -> 3965704.9 | J8: =H8/2 -> 23794229 | K8: =H8 -> 47588459
A9: ='Livestock Count'!A9 -> Dadra & Nagar Haveli | B9: ='Livestock Count'!G9 -> 48365 | C9: =B9*Assumptions!B2*Assumptions!B3 -> 11970.338 | D9: =(B9+C9)*Assumptions!B4 -> 57318.571 | E9: 0 | F9: =(D9-E9)*2 -> 114637.14 | G9: =F9*(1+Assumptions!B5+Assumptions!B6+Assumptions!B7) -> 126100.86 | H9: =G9*(1+Assumptions!B8+Assumptions!B9) -> 145015.98 | I9: =H9/12 -> 12084.665 | J9: =H9/2 -> 72507.992 | K9: =H9 -> 145015.98
A10: ='Livestock Count'!A10 -> Daman & Diu | B10: ='Livestock Count'!G10 -> 3269 | C10: =B10*Assumptions!B2*Assumptions!B3 -> 809.0775 | D10: =(B10+C10)*Assumptions!B4 -> 3874.1736 | E10: 0 | F10: =(D10-E10)*2 -> 7748.3472 | G10: =F10*(1+Assumptions!B5+Assumptions!B6+Assumptions!B7) -> 8523.182 | H10: =G10*(1+Assumptions!B8+Assumptions!B9) -> 9801.6593 | I10: =H10/12 -> 816.80494 | J10: =H10/2 -> 4900.8296 | K10: =H10 -> 9801.6593
A11: ='Livestock Count'!A11 -> Delhi | B11: ='Livestock Count'!G11 -> 356323 | C11: =B11*Assumptions!B2*Assumptions!B3 -> 88189.943 | D11: =(B11+C11)*Assumptions!B4 -> 422287.3 | E11: 0 | F11: =(D11-E11)*2 -> 844574.59 | G11: =F11*(1+Assumptions!B5+Assumptions!B6+Assumptions!B7) -> 929032.05 | H11: =G11*(1+Assumptions!B8+Assumptions!B9) -> 1068386.9 | I11: =H11/12 -> 89032.238 | J11: =H11/2 -> 534193.43 | K11: =H11 -> 1068386.9
A12: ='Livestock Count'!A12 -> Goa | B12: ='Livestock Count'!G12 -> 132388 | C12: =B12*Assumptions!B2*Assumptions!B3 -> 32766.03 | D12: =(B12+C12)*Assumptions!B4 -> 156896.33 | E12: 0 | F12: =(D12-E12)*2 -> 313792.66 | G12: =F12*(1+Assumptions!B5+Assumptions!B6+Assumptions!B7) -> 345171.92 | H12: =G12*(1+Assumptions!B8+Assumptions!B9) -> 396947.71 | I12: =H12/12 -> 33078.976 | J12: =H12/2 -> 198473.86 | K12: =H12 -> 396947.71
A13: ='Livestock Count'!A13 -> Gujarat | B13: ='Livestock Count'!G13 -> 26832552 | C13: =B13*Assumptions!B2*Assumptions!B3 -> 6641056.6 | D13: =(B13+C13)*Assumptions!B4 -> 31799928 | E13: 0 | F13: =(D13-E13)*2 -> 63599856 | G13: =F13*(1+Assumptions!B5+Assumptions!B6+Assumptions!B7) -> 69959842 | H13: =G13*(1+Assumptions!B8+Assumptions!B9) -> 80453818 | I13: =H13/12 -> 6704484.9 | J13: =H13/2 -> 40226909 | K13: =H13 -> 80453818
A14: ='Livestock Count'!A14 -> Haryana | B14: ='Livestock Count'!G14 -> 7027955 | C14: =B14*Assumptions!B2*Assumptions!B3 -> 1739418.9 | D14: =(B14+C14)*Assumptions!B4 -> 8329005.2 | E14: 0 | F14: =(D14-E14)*2 -> 16658010 | G14: =F14*(1+Assumptions!B5+Assumptions!B6+Assumptions!B7) -> 18323811 | H14: =G14*(1+Assumptions!B8+Assumptions!B9) -> 21072383 | I14: =H14/12 -> 1756031.9 | J14: =H14/2 -> 10536192 | K14: =H14 -> 21072383
A15: ='Livestock Count'!A15 -> Himachal Pradesh | B15: ='Livestock Count'!G15 -> 4376817 | C15: =B15*Assumptions!B2*Assumptions!B3 -> 1083262.2 | D15: =(B15+C15)*Assumptions!B4 -> 5187075.2 | E15: 0 | F15: =(D15-E15)*2 -> 10374150 | G15: =F15*(1+Assumptions!B5+Assumptions!B6+Assumptions!B7) -> 11411566 | H15: =G15*(1+Assumptions!B8+Assumptions!B9) -> 13123300 | I15: =H15/12 -> 1093608.4 | J15: =H15/2 -> 6561650.2 | K15: =H15 -> 13123300
A16: ='Livestock Count'!A16 -> Jammu & Kashmir | B16: ='Livestock Count'!G16 -> 8209005 | C16: =B16*Assumptions!B2*Assumptions!B3 -> 2031728.7 | D16: =(B16+C16)*Assumptions!B4 -> 9728697.1 | E16: 0 | F16: =(D16-E16)*2 -> 19457394 | G16: =F16*(1+Assumptions!B5+Assumptions!B6+Assumptions!B7) -> 21403134 | H16: =G16*(1+Assumptions!B8+Assumptions!B9) -> 24613604 | I16: =H16/12 -> 2051133.6 | J16: =H16/2 -> 12306802 | K16: =H16 -> 24613604
A17: ='Livestock Count'!A17 -> Jharkhand | B17: ='Livestock Count'!G17 -> 23612694 | C17: =B17*Assumptions!B2*Assumptions!B3 -> 5844141.8 | D17: =(B17+C17)*Assumptions!B4 -> 27983994 | E17: 0 | F17: =(D17-E17)*2 -> 55967988 | G17: =F17*(1+Assumptions!B5+Assumptions!B6+Assumptions!B7) -> 61564787 | H17: =G17*(1+Assumptions!B8+Assumptions!B9) -> 70799505 | I17: =H17/12 -> 5899958.7 | J17: =H17/2 -> 35399752 | K17: =H17 -> 70799505
A18: ='Livestock Count'!A18 -> Karnataka | B18: ='Livestock Count'!G18 -> 28997520 | C18: =B18*Assumptions!B2*Assumptions!B3 -> 7176886.2 | D18: =(B18+C18)*Assumptions!B4 -> 34365686 | E18: 0 | F18: =(D18-E18)*2 -> 68731372 | G18: =F18*(1+Assumptions!B5+Assumptions!B6+Assumptions!B7) -> 75604509 | H18: =G18*(1+Assumptions!B8+Assumptions!B9) -> 86945185 | I18: =H18/12 -> 7245432.1 | J18: =H18/2 -> 43472593 | K18: =H18 -> 86945185
A19: ='Livestock Count'!A19 -> Kerala | B19: ='Livestock Count'!G19 -> 2908006 | C19: =B19*Assumptions!B2*Assumptions!B3 -> 719731.48 | D19: =(B19+C19)*Assumptions!B4 -> 3446350.6 | E19: 0 | F19: =(D19-E19)*2 -> 6892701.2 | G19: =F19*(1+Assumptions!B5+Assumptions!B6+Assumptions!B7) -> 7581971.3 | H19: =G19*(1+Assumptions!B8+Assumptions!B9) -> 8719267 | I19: =H19/12 -> 726605.59 | J19: =H19/2 -> 4359633.5 | K19: =H19 -> 8719267
A20: ='Livestock Count'!A20 -> Lakshadweep | B20: ='Livestock Count'!G20 -> 45697 | C20: =B20*Assumptions!B2*Assumptions!B3 -> 11310.008 | D20: =(B20+C20)*Assumptions!B4 -> 54156.657 | E20: 0 | F20: =(D20-E20)*2 -> 108313.31 | G20: =F20*(1+Assumptions!B5+Assumptions!B6+Assumptions!B7) -> 119144.65 | H20: =G20*(1+Assumptions!B8+Assumptions!B9) -> 137016.34 | I20: =H20/12 -> 11418.029 | J20: =H20/2 -> 68508.171 | K20: =H20 -> 137016.34
A21: ='Livestock Count'!A21 -> Madhya Pradesh | B21: ='Livestock Count'!G21 -> 40611684 | C21: =B21*Assumptions!B2*Assumptions!B3 -> 10051392 | D21: =(B21+C21)*Assumptions!B4 -> 48129922 | E21: 0 | F21: =(D21-E21)*2 -> 96259844 | G21: =F21*(1+Assumptions!B5+Assumptions!B6+Assumptions!B7) -> 1.0588583e+08 | H21: =G21*(1+Assumptions!B8+Assumptions!B9) -> 1.217687e+08 | I21: =H21/12 -> 10147392 | J21: =H21/2 -> 60884351 | K21: =H21 -> 1.217687e+08
A22: ='Livestock Count'!A22 -> Maharashtra | B22: ='Livestock Count'!G22 -> 33042208 | C22: =B22*Assumptions!B2*Assumptions!B3 -> 8177946.5 | D22: =(B22+C22)*Assumptions!B4 -> 39159147 | E22: 0 | F22: =(D22-E22)*2 -> 78318294 | G22: =F22*(1+Assumptions!B5+Assumptions!B6+Assumptions!B7) -> 86150123 | H22: =G22*(1+Assumptions!B8+Assumptions!B9) -> 99072641 | I22: =H22/12 -> 8256053.4 | J22: =H22/2 -> 49536321 | K22: =H22 -> 99072641
A23: ='Livestock Count'!A23 -> Manipur | B23: ='Livestock Count'!G23 -> 540575 | C23: =B23*Assumptions!B2*Assumptions!B3 -> 133792.31 | D23: =(B23+C23)*Assumptions!B4 -> 640648.95 | E23: 0 | F23: =(D23-E23)*2 -> 1281297.9 | G23: =F23*(1+Assumptions!B5+Assumptions!B6+Assumptions!B7) -> 1409427.7 | H23: =G23*(1+Assumptions!B8+Assumptions!B9) -> 1620841.8 | I23: =H23/12 -> 135070.15 | J23: =H23/2 -> 810420.92 | K23: =H23 -> 1620841.8
A24: ='Livestock Count'!A24 -> Meghalaya | B24: ='Livestock Count'!G24 -> 2038830 | C24: =B24*Assumptions!B2*Assumptions!B3 -> 504610.42 | D24: =(B24+C24)*Assumptions!B4 -> 2416268.4 | E24: 0 | F24: =(D24-E24)*2 -> 4832536.8 | G24: =F24*(1+Assumptions!B5+Assumptions!B6+Assumptions!B7) -> 5315790.5 | H24: =G24*(1+Assumptions!B8+Assumptions!B9) -> 6113159.1 | I24: =H24/12 -> 509429.92 | J24: =H24/2 -> 3056579.5 | K24: =H24 -> 6113159.1
A25: ='Livestock Count'!A25 -> Mizoram | B25: ='Livestock Count'!G25 -> 355580 | C25: =B25*Assumptions!B2*Assumptions!B3 -> 88006.05 | D25: =(B25+C25)*Assumptions!B4 -> 421406.75 | E25: 0 | F25: =(D25-E25)*2 -> 842813.49 | G25: =F25*(1+Assumptions!B5+Assumptions!B6+Assumptions!B7) -> 927094.84 | H25: =G25*(1+Assumptions!B8+Assumptions!B9) -> 1066159.1 | I25: =H25/12 -> 88846.589 | J25: =H25/2 -> 533079.54 | K25: =H25 -> 1066159.1
A26: ='Livestock Count'!A26 -> Nagaland | B26: ='Livestock Count'!G26 -> 530608 | C26: =B26*Assumptions!B2*Assumptions!B3 -> 131325.48 | D26: =(B26+C26)*Assumptions!B4 -> 628836.81 | E26: 0 | F26: =(D26-E26)*2 -> 1257673.6 | G26: =F26*(1+Assumptions!B5+Assumptions!B6+Assumptions!B7) -> 1383441 | H26: =G26*(1+Assumptions!B8+Assumptions!B9) -> 1590957.1 | I26: =H26/12 -> 132579.76 | J26: =H26/2 -> 795478.56 | K26: =H26 -> 1590957.1
A27: ='Livestock Count'!A27 -> Odisha | B27: ='Livestock Count'!G27 -> 18170057 | C27: =B27*Assumptions!B2*Assumptions!B3 -> 4497089.1 | D27: =(B27+C27)*Assumptions!B4 -> 21533789 | E27: 0 | F27: =(D27-E27)*2 -> 43067578 | G27: =F27*(1+Assumptions!B5+Assumptions!B6+Assumptions!B7) -> 47374335 | H27: =G27*(1+Assumptions!B8+Assumptions!B9) -> 54480486 | I27: =H27/12 -> 4540040.5 | J27: =H27/2 -> 27240243 | K27: =H27 -> 54480486
A28: ='Livestock Count'!A28 -> Puducherry | B28: ='Livestock Count'!G28 -> 151334 | C28: =B28*Assumptions!B2*Assumptions!B3 -> 37455.165 | D28: =(B28+C28)*Assumptions!B4 -> 179349.71 | E28: 0 | F28: =(D28-E28)*2 -> 358699.41 | G28: =F28*(1+Assumptions!B5+Assumptions!B6+Assumptions!B7) -> 394569.35 | H28: =G28*(1+Assumptions!B8+Assumptions!B9) -> 453754.76 | I28: =H28/12 -> 37812.897 | J28: =H28/2 -> 226877.38 | K28: =H28 -> 453754.76
A29: ='Livestock Count'!A29 -> Punjab | B29: ='Livestock Count'!G29 -> 7033877 | C29: =B29*Assumptions!B2*Assumptions!B3 -> 1740884.6 | D29: =(B29+C29)*Assumptions!B4 -> 8336023.5 | E29: 0 | F29: =(D29-E29)*2 -> 16672047 | G29: =F29*(1+Assumptions!B5+Assumptions!B6+Assumptions!B7) -> 18339252 | H29: =G29*(1+Assumptions!B8+Assumptions!B9) -> 21090139 | I29: =H29/12 -> 1757511.6 | J29: =H29/2 -> 10545070 | K29: =H29 -> 21090139
A30: ='Livestock Count'!A30 -> Rajasthan | B30: ='Livestock Count'!G30 -> 56529814 | C30: =B30*Assumptions!B2*Assumptions!B3 -> 13991129 | D30: =(B30+C30)*Assumptions!B4 -> 66994896 | E30: 0 | F30: =(D30-E30)*2 -> 1.3398979e+08 | G30: =F30*(1+Assumptions!B5+Assumptions!B6+Assumptions!B7) -> 1.4738877e+08 | H30: =G30*(1+Assumptions!B8+Assumptions!B9) -> 1.6949709e+08 | I30: =H30/12 -> 14124757 | J30: =H30/2 -> 84748543 | K30: =H30 -> 1.6949709e+08
A31: ='Livestock Count'!A31 -> Sikkim | B31: ='Livestock Count'!G31 -> 268996 | C31: =B31*Assumptions!B2*Assumptions!B3 -> 66576.51 | D31: =(B31+C31)*Assumptions!B4 -> 318793.88 | E31: 0 | F31: =(D31-E31)*2 -> 637587.77 | G31: =F31*(1+Assumptions!B5+Assumptions!B6+Assumptions!B7) -> 701346.55 | H31: =G31*(1+Assumptions!B8+Assumptions!B9) -> 806548.53 | I31: =H31/12 -> 67212.377 | J31: =H31/2 -> 403274.26 | K31: =H31 -> 806548.53
A32: ='Livestock Count'!A32 -> Tamil Nadu | B32: ='Livestock Count'!G32 -> 24493464 | C32: =B32*Assumptions!B2*Assumptions!B3 -> 6062132.3 | D32: =(B32+C32)*Assumptions!B4 -> 29027817 | E32: 0 | F32: =(D32-E32)*2 -> 58055633 | G32: =F32*(1+Assumptions!B5+Assumptions!B6+Assumptions!B7) -> 63861196 | H32: =G32*(1+Assumptions!B8+Assumptions!B9) -> 73440376 | I32: =H32/12 -> 6120031.3 | J32: =H32/2 -> 36720188 | K32: =H32 -> 73440376
A33: ='Livestock Count'!A33 -> Telangana | B33: ='Livestock Count'!G33 -> 32634568 | C33: =B33*Assumptions!B2*Assumptions!B3 -> 8077055.6 | D33: =(B33+C33)*Assumptions!B4 -> 38676042 | E33: 0 | F33: =(D33-E33)*2 -> 77352085 | G33: =F33*(1+Assumptions!B5+Assumptions!B6+Assumptions!B7) -> 85087293 | H33: =G33*(1+Assumptions!B8+Assumptions!B9) -> 97850387 | I33: =H33/12 -> 8154198.9 | J33: =H33/2 -> 48925194 | K33: =H33 -> 97850387
A34: ='Livestock Count'!A34 -> Tripura | B34: ='Livestock Count'!G34 -> 1317861 | C34: =B34*Assumptions!B2*Assumptions!B3 -> 326170.6 | D34: =(B34+C34)*Assumptions!B4 -> 1561830 | E34: 0 | F34: =(D34-E34)*2 -> 3123660 | G34: =F34*(1+Assumptions!B5+Assumptions!B6+Assumptions!B7) -> 3436026 | H34: =G34*(1+Assumptions!B8+Assumptions!B9) -> 3951429.9 | I34: =H34/12 -> 329285.83 | J34: =H34/2 -> 1975715 | K34: =H34 -> 3951429.9
A35: ='Livestock Count'!A35 -> Uttar Pradesh | B35: ='Livestock Count'!G35 -> 67909854 | C35: =B35*Assumptions!B2*Assumptions!B3 -> 16807689 | D35: =(B35+C35)*Assumptions!B4 -> 80481666 | E35: 0 | F35: =(D35-E35)*2 -> 1.6096333e+08 | G35: =F35*(1+Assumptions!B5+Assumptions!B6+Assumptions!B7) -> 1.7705966e+08 | H35: =G35*(1+Assumptions!B8+Assumptions!B9) -> 2.0361861e+08 | I35: =H35/12 -> 16968218 | J35: =H35/2 -> 1.0180931e+08 | K35: =H35 -> 2.0361861e+08
A36: ='Livestock Count'!A36 -> Uttarakhand | B36: ='Livestock Count'!G36 -> 4392686 | C36: =B36*Assumptions!B2*Assumptions!B3 -> 1087189.8 | D36: =(B36+C36)*Assumptions!B4 -> 5205882 | E36: 0 | F36: =(D36-E36)*2 -> 10411764 | G36: =F36*(1+Assumptions!B5+Assumptions!B6+Assumptions!B7) -> 11452940 | H36: =G36*(1+Assumptions!B8+Assumptions!B9) -> 13170881 | I36: =H36/12 -> 1097573.5 | J36: =H36/2 -> 6585440.7 | K36: =H36 -> 13170881
A37: ='Livestock Count'!A37 -> West Bengal | B37: ='Livestock Count'!G37 -> 37481419 | C37: =B37*Assumptions!B2*Assumptions!B3 -> 9276651.2 | D37: =(B37+C37)*Assumptions!B4 -> 44420167 | E37: 0 | F37: =(D37-E37)*2 -> 88840333 | G37: =F37*(1+Assumptions!B5+Assumptions!B6+Assumptions!B7) -> 97724367 | H37: =G37*(1+Assumptions!B8+Assumptions!B9) -> 1.1238302e+08 | I37: =H37/12 -> 9365251.8 | J37: =H37/2 -> 56191511 | K37: =H37 -> 1.1238302e+08

Sheet Last Year Procurement
A1: Vaccine | B1: Total Doses (FY 2024-25) | C1: Source / Notes
A2: FMD | B2: 348000000 | C2: DAHD Annual Report 2024-25
A3: Brucellosis | B3: 3939000 | C3: DAHD Annual Report 2024-25
A4: PPR | B4: 27600000 | C4: DAHD Annual Report 2024-25
A5: CSF | B5: 542000 | C5: DAHD Annual Report 2024-25
A6: LSD | C6: State driven – user input

Sheet State Prioritisation
A1: State/UT | B1: Total Eligible Livestock | C1: Livestock Share (%) | D1: High Disease Burden (Editable) | E1: Border / Migratory Risk (Editable) | F1: Programmatic Priority (Editable) | G1: Composite Priority Index | H1: Priority Category
A2: ='Livestock Count'!A2 -> Andaman & Nicobar Islands | B2: ='Livestock Count'!G2 -> 145392 | C2: =B2/SUM(B2:B37) -> 0.00027149918 | D2: 1 | E2: 1 | F2: 1 | G2: =C2*D2*E2*F2 -> 0.00027149918 | H2: =IF(G2>=PERCENTILE($G$2:$G$37,0.75),"High",IF(G2>=PERCENTILE($G$2:$G$37,0.4),"Medium","Standard")) -> Standard
A3: ='Livestock Count'!A3 -> Andhra Pradesh | B3: ='Livestock Count'!G3 -> 34060648 | C3: =B3/SUM(B2:B37) -> 0.063603485 | D3: 1 | E3: 1 | F3: 1 | G3: =C3*D3*E3*F3 -> 0.063603485 | H3: =IF(G3>=PERCENTILE($G$2:$G$37,0.75),"High",IF(G3>=PERCENTILE($G$2:$G$37,0.4),"Medium","Standard")) -> High
A4: ='Livestock Count'!A4 -> Arunachal Pradesh | B4: ='Livestock Count'!G4 -> 784148 | C4: =B4/SUM(B2:B37) -> 0.0014642865 | D4: 1 | E4: 1 | F4: 1 | G4: =C4*D4*E4*F4 -> 0.0014642865 | H4: =IF(G4>=PERCENTILE($G$2:$G$37,0.75),"High",IF(G4>=PERCENTILE($G$2:$G$37,0.4),"Medium","Standard")) -> Standard
A5: ='Livestock Count'!A5 -> Assam | B5: ='Livestock Count'!G5 -> 18077227 | C5: =B5/SUM(B2:B37) -> 0.033756687 | D5: 1 | E5: 1 | F5: 1 | G5: =C5*D5*E5*F5 -> 0.033756687 | H5: =IF(G5>=PERCENTILE($G$2:$G$37,0.75),"High",IF(G5>=PERCENTILE($G$2:$G$37,0.4),"Medium","Standard")) -> Medium
A6: ='Livestock Count'!A6 -> Bihar | B6: ='Livestock Count'!G6 -> 36495801 | C6: =B6/SUM(B2:B37) -> 0.068150792 | D6: 1 | E6: 1 | F6: 1 | G6: =C6*D6*E6*F6 -> 0.068150792 | H6: =IF(G6>=PERCENTILE($G$2:$G$37,0.75),"High",IF(G6>=PERCENTILE($G$2:$G$37,0.4),"Medium","Standard")) -> High
A7: ='Livestock Count'!A7 -> Chandigarh | B7: ='Livestock Count'!G7 -> 26753 | C7: =B7/SUM(B2:B37) -> 4.9957477e-05 | D7: 1 | E7: 1 | F7: 1 | G7: =C7*D7*E7*F7 -> 4.9957477e-05 | H7: =IF(G7>=PERCENTILE($G$2:$G$37,0.75),"High",IF(G7>=PERCENTILE($G$2:$G$37,0.4),"Medium","Standard")) -> Standard
A8: ='Livestock Count'!A8 -> Chhattisgarh | B8: ='Livestock Count'!G8 -> 15871463 | C8: =B8/SUM(B2:B37) -> 0.029637732 | D8: 1 | E8: 1 | F8: 1 | G8: =C8*D8*E8*F8 -> 0.029637732 | H8: =IF(G8>=PERCENTILE($G$2:$G$37,0.75),"High",IF(G8>=PERCENTILE($G$2:$G$37,0.4),"Medium","Standard")) -> Medium
A9: ='Livestock Count'!A9 -> Dadra & Nagar Haveli | B9: ='Livestock Count'!G9 -> 48365 | C9: =B9/SUM(B2:B37) -> 9.0314857e-05 | D9: 1 | E9: 1 | F9: 1 | G9: =C9*D9*E9*F9 -> 9.0314857e-05 | H9: =IF(G9>=PERCENTILE($G$2:$G$37,0.75),"High",IF(G9>=PERCENTILE($G$2:$G$37,0.4),"Medium","Standard")) -> Standard
A10: ='Livestock Count'!A10 -> Daman & Diu | B10: ='Livestock Count'!G10 -> 3269 | C10: =B10/SUM(B2:B37) -> 6.1043992e-06 | D10: 1 | E10: 1 | F10: 1 | G10: =C10*D10*E10*F10 -> 6.1043992e-06 | H10: =IF(G10>=PERCENTILE($G$2:$G$37,0.75),"High",IF(G10>=PERCENTILE($G$2:$G$37,0.4),"Medium","Standard")) -> Standard
A11: ='Livestock Count'!A11 -> Delhi | B11: ='Livestock Count'!G11 -> 356323 | C11: =B11/SUM(B2:B37) -> 0.00066538325 | D11: 1 | E11: 1 | F11: 1 | G11: =C11*D11*E11*F11 -> 0.00066538325 | H11: =IF(G11>=PERCENTILE($G$2:$G$37,0.75),"High",IF(G11>=PERCENTILE($G$2:$G$37,0.4),"Medium","Standard")) -> Standard
A12: ='Livestock Count'!A12 -> Goa | B12: ='Livestock Count'!G12 -> 132388 | C12: =B12/SUM(B2:B37) -> 0.00024721603 | D12: 1 | E12: 1 | F12: 1 | G12: =C12*D12*E12*F12 -> 0.00024721603 | H12: =IF(G12>=PERCENTILE($G$2:$G$37,0.75),"High",IF(G12>=PERCENTILE($G$2:$G$37,0.4),"Medium","Standard")) -> Standard
A13: ='Livestock Count'!A13 -> Gujarat | B13: ='Livestock Count'!G13 -> 26832552 | C13: =B13/SUM(B2:B37) -> 0.050106029 | D13: 1 | E13: 1 | F13: 1 | G13: =C13*D13*E13*F13 -> 0.050106029 | H13: =IF(G13>=PERCENTILE($G$2:$G$37,0.75),"High",IF(G13>=PERCENTILE($G$2:$G$37,0.4),"Medium","Standard")) -> Medium
A14: ='Livestock Count'!A14 -> Haryana | B14: ='Livestock Count'!G14 -> 7027955 | C14: =B14/SUM(B2:B37) -> 0.013123721 | D14: 1 | E14: 1 | F14: 1 | G14: =C14*D14*E14*F14 -> 0.013123721 | H14: =IF(G14>=PERCENTILE($G$2:$G$37,0.75),"High",IF(G14>=PERCENTILE($G$2:$G$37,0.4),"Medium","Standard")) -> Medium
A15: ='Livestock Count'!A15 -> Himachal Pradesh | B15: ='Livestock Count'!G15 -> 4376817 | C15: =B15/SUM(B2:B37) -> 0.0081730921 | D15: 1 | E15: 1 | F15: 1 | G15: =C15*D15*E15*F15 -> 0.0081730921 | H15: =IF(G15>=PERCENTILE($G$2:$G$37,0.75),"High",IF(G15>=PERCENTILE($G$2:$G$37,0.4),"Medium","Standard")) -> Medium
A16: ='Livestock Count'!A16 -> Jammu & Kashmir | B16: ='Livestock Count'!G16 -> 8209005 | C16: =B16/SUM(B2:B37) -> 0.015329166 | D16: 1 | E16: 1 | F16: 1 | G16: =C16*D16*E16*F16 -> 0.015329166 | H16: =IF(G16>=PERCENTILE($G$2:$G$37,0.75),"High",IF(G16>=PERCENTILE($G$2:$G$37,0.4),"Medium","Standard")) -> Medium
A17: ='Livestock Count'!A17 -> Jharkhand | B17: ='Livestock Count'!G17 -> 23612694 | C17: =B17/SUM(B2:B37) -> 0.044093395 | D17: 1 | E17: 1 | F17: 1 | G17: =C17*D17*E17*F17 -> 0.044093395 | H17: =IF(G17>=PERCENTILE($G$2:$G$37,0.75),"High",IF(G17>=PERCENTILE($G$2:$G$37,0.4),"Medium","Standard")) -> Medium
A18: ='Livestock Count'!A18 -> Karnataka | B18: ='Livestock Count'!G18 -> 28997520 | C18: =B18/SUM(B2:B37) -> 0.054148803 | D18: 1 | E18: 1 | F18: 1 | G18: =C18*D18*E18*F18 -> 0.054148803 | H18: =IF(G18>=PERCENTILE($G$2:$G$37,0.75),"High",IF(G18>=PERCENTILE($G$2:$G$37,0.4),"Medium","Standard")) -> High
A19: ='Livestock Count'!A19 -> Kerala | B19: ='Livestock Count'!G19 -> 2908006 | C19: =B19/SUM(B2:B37) -> 0.0054302935 | D19: 1 | E19: 1 | F19: 1 | G19: =C19*D19*E19*F19 -> 0.0054302935 | H19: =IF(G19>=PERCENTILE($G$2:$G$37,0.75),"High",IF(G19>=PERCENTILE($G$2:$G$37,0.4),"Medium","Standard")) -> Medium
A20: ='Livestock Count'!A20 -> Lakshadweep | B20: ='Livestock Count'!G20 -> 45697 | C20: =B20/SUM(B2:B37) -> 8.5332741e-05 | D20: 1 | E20: 1 | F20: 1 | G20: =C20*D20*E20*F20 -> 8.5332741e-05 | H20: =IF(G20>=PERCENTILE($G$2:$G$37,0.75),"High",IF(G20>=PERCENTILE($G$2:$G$37,0.4),"Medium","Standard")) -> Standard
A21: ='Livestock Count'!A21 -> Madhya Pradesh | B21: ='Livestock Count'!G21 -> 40611684 | C21: =B21/SUM(B2:B37) -> 0.075836626 | D21: 1 | E21: 1 | F21: 1 | G21: =C21*D21*E21*F21 -> 0.075836626 | H21: =IF(G21>=PERCENTILE($G$2:$G$37,0.75),"High",IF(G21>=PERCENTILE($G$2:$G$37,0.4),"Medium","Standard")) -> High
A22: ='Livestock Count'!A22 -> Maharashtra | B22: ='Livestock Count'!G22 -> 33042208 | C22: =B22/SUM(B2:B37) -> 0.061701691 | D22: 1 | E22: 1 | F22: 1 | G22: =C22*D22*E22*F22 -> 0.061701691 | H22: =IF(G22>=PERCENTILE($G$2:$G$37,0.75),"High",IF(G22>=PERCENTILE($G$2:$G$37,0.4),"Medium","Standard")) -> High
A23: ='Livestock Count'!A23 -> Manipur | B23: ='Livestock Count'!G23 -> 540575 | C23: =B23/SUM(B2:B37) -> 0.001009448 | D23: 1 | E23: 1 | F23: 1 | G23: =C23*D23*E23*F23 -> 0.001009448 | H23: =IF(G23>=PERCENTILE($G$2:$G$37,0.75),"High",IF(G23>=PERCENTILE($G$2:$G$37,0.4),"Medium","Standard")) -> Standard
A24: ='Livestock Count'!A24 -> Meghalaya | B24: ='Livestock Count'!G24 -> 2038830 | C24: =B24/SUM(B2:B37) -> 0.0038072292 | D24: 1 | E24: 1 | F24: 1 | G24: =C24*D24*E24*F24 -> 0.0038072292 | H24: =IF(G24>=PERCENTILE($G$2:$G$37,0.75),"High",IF(G24>=PERCENTILE($G$2:$G$37,0.4),"Medium","Standard")) -> Medium
A25: ='Livestock Count'!A25 -> Mizoram | B25: ='Livestock Count'!G25 -> 355580 | C25: =B25/SUM(B2:B37) -> 0.0006639958 | D25: 1 | E25: 1 | F25: 1 | G25: =C25*D25*E25*F25 -> 0.0006639958 | H25: =IF(G25>=PERCENTILE($G$2:$G$37,0.75),"High",IF(G25>=PERCENTILE($G$2:$G$37,0.4),"Medium","Standard")) -> Standard
A26: ='Livestock Count'!A26 -> Nagaland | B26: ='Livestock Count'!G26 -> 530608 | C26: =B26/SUM(B2:B37) -> 0.00099083605 | D26: 1 | E26: 1 | F26: 1 | G26: =C26*D26*E26*F26 -> 0.00099083605 | H26: =IF(G26>=PERCENTILE($G$2:$G$37,0.75),"High",IF(G26>=PERCENTILE($G$2:$G$37,0.4),"Medium","Standard")) -> Standard
A27: ='Livestock Count'!A27 -> Odisha | B27: ='Livestock Count'!G27 -> 18170057 | C27: =B27/SUM(B2:B37) -> 0.033930034 | D27: 1 | E27: 1 | F27: 1 | G27: =C27*D27*E27*F27 -> 0.033930034 | H27: =IF(G27>=PERCENTILE($G$2:$G$37,0.75),"High",IF(G27>=PERCENTILE($G$2:$G$37,0.4),"Medium","Standard")) -> Medium
A28: ='Livestock Count'!A28 -> Puducherry | B28: ='Livestock Count'!G28 -> 151334 | C28: =B28/SUM(B2:B37) -> 0.00028259503 | D28: 1 | E28: 1 | F28: 1 | G28: =C28*D28*E28*F28 -> 0.00028259503 | H28: =IF(G28>=PERCENTILE($G$2:$G$37,0.75),"High",IF(G28>=PERCENTILE($G$2:$G$37,0.4),"Medium","Standard")) -> Standard
A29: ='Livestock Count'!A29 -> Punjab | B29: ='Livestock Count'!G29 -> 7033877 | C29: =B29/SUM(B2:B37) -> 0.013134779 | D29: 1 | E29: 1 | F29: 1 | G29: =C29*D29*E29*F29 -> 0.013134779 | H29: =IF(G29>=PERCENTILE($G$2:$G$37,0.75),"High",IF(G29>=PERCENTILE($G$2:$G$37,0.4),"Medium","Standard")) -> Medium
A30: ='Livestock Count'!A30 -> Rajasthan | B30: ='Livestock Count'!G30 -> 56529814 | C30: =B30/SUM(B2:B37) -> 0.1055615 | D30: 1 | E30: 1 | F30: 1 | G30: =C30*D30*E30*F30 -> 0.1055615 | H30: =IF(G30>=PERCENTILE($G$2:$G$37,0.75),"High",IF(G30>=PERCENTILE($G$2:$G$37,0.4),"Medium","Standard")) -> High
A31: ='Livestock Count'!A31 -> Sikkim | B31: ='Livestock Count'!G31 -> 268996 | C31: =B31/SUM(B2:B37) -> 0.00050231232 | D31: 1 | E31: 1 | F31: 1 | G31: =C31*D31*E31*F31 -> 0.00050231232 | H31: =IF(G31>=PERCENTILE($G$2:$G$37,0.75),"High",IF(G31>=PERCENTILE($G$2:$G$37,0.4),"Medium","Standard")) -> Standard
A32: ='Livestock Count'!A32 -> Tamil Nadu | B32: ='Livestock Count'!G32 -> 24493464 | C32: =B32/SUM(B2:B37) -> 0.04573811 | D32: 1 | E32: 1 | F32: 1 | G32: =C32*D32*E32*F32 -> 0.04573811 | H32: =IF(G32>=PERCENTILE($G$2:$G$37,0.75),"High",IF(G32>=PERCENTILE($G$2:$G$37,0.4),"Medium","Standard")) -> Medium
A33: ='Livestock Count'!A33 -> Telangana | B33: ='Livestock Count'!G33 -> 32634568 | C33: =B33/SUM(B2:B37) -> 0.06094048 | D33: 1 | E33: 1 | F33: 1 | G33: =C33*D33*E33*F33 -> 0.06094048 | H33: =IF(G33>=PERCENTILE($G$2:$G$37,0.75),"High",IF(G33>=PERCENTILE($G$2:$G$37,0.4),"Medium","Standard")) -> High
A34: ='Livestock Count'!A34 -> Tripura | B34: ='Livestock Count'!G34 -> 1317861 | C34: =B34/SUM(B2:B37) -> 0.0024609207 | D34: 1 | E34: 1 | F34: 1 | G34: =C34*D34*E34*F34 -> 0.0024609207 | H34: =IF(G34>=PERCENTILE($G$2:$G$37,0.75),"High",IF(G34>=PERCENTILE($G$2:$G$37,0.4),"Medium","Standard")) -> Standard
A35: ='Livestock Count'!A35 -> Uttar Pradesh | B35: ='Livestock Count'!G35 -> 67909854 | C35: =B35/SUM(B2:B37) -> 0.12681213 | D35: 1 | E35: 1 | F35: 1 | G35: =C35*D35*E35*F35 -> 0.12681213 | H35: =IF(G35>=PERCENTILE($G$2:$G$37,0.75),"High",IF(G35>=PERCENTILE($G$2:$G$37,0.4),"Medium","Standard")) -> High
A36: ='Livestock Count'!A36 -> Uttarakhand | B36: ='Livestock Count'!G36 -> 4392686 | C36: =B36/SUM(B2:B37) -> 0.0082027252 | D36: 1 | E36: 1 | F36: 1 | G36: =C36*D36*E36*F36 -> 0.0082027252 | H36: =IF(G36>=PERCENTILE($G$2:$G$37,0.75),"High",IF(G36>=PERCENTILE($G$2:$G$37,0.4),"Medium","Standard")) -> Medium
A37: ='Livestock Count'!A37 -> West Bengal | B37: ='Livestock Count'!G37 -> 37481419 | C37: =B37/SUM(B2:B37) -> 0.069991295 | D37: 1 | E37: 1 | F37: 1 | G37: =C37*D37*E37*F37 -> 0.069991295 | H37: =IF(G37>=PERCENTILE($G$2:$G$37,0.75),"High",IF(G37>=PERCENTILE($G$2:$G$37,0.4),"Medium","Standard")) -> High

Sheet Dashboard
A1: DAHD Vaccine Procurement Dashboard
A3: Total Annual Demand (All States) | B3: =SUM('Demand Estimation'!J:J) -> 8.0283571e+08
A5: Total Monthly Demand | B5: =SUM('Demand Estimation'!H:H) -> 1.6056714e+09
A7: Total Half-Yearly Demand | B7: =SUM('Demand Estimation'!I:I) -> 1.3380595e+08
A9: Note:
A10: All figures are auto-derived from census, assumptions, and priority index.

Sheet FMD Demand
A1: State/UT | B1: Eligible Animals | C1: New Birth Eligible | D1: Adjusted Eligible (Coverage) | E1: Current Inventory | F1: Annual Dose Requirement | G1: After Losses | H1: After Buffer & Campaign | I1: Monthly Demand | J1: Half-Yearly Demand | K1: Annual Demand
A2: Andaman & Nicobar Islands | B2: =SUM('Livestock Count'!B2:F2) -> 145392 | C2: =B2*Assumptions!B2*Assumptions!B3 -> 35984.52 | D2: =(B2+C2)*Assumptions!B4 -> 172307.69 | E2: 0 | F2: =(D2-E2)*2 -> 344615.39 | G2: =F2*(1+Assumptions!B5+Assumptions!B6+Assumptions!B7) -> 379076.93 | H2: =G2*(1+Assumptions!B8+Assumptions!B9) -> 435938.47 | I2: =H2/12 -> 36328.205 | J2: =H2/2 -> 217969.23 | K2: =H2 -> 435938.47
A3: Andhra Pradesh | B3: =SUM('Livestock Count'!B3:F3) -> 34060648 | C3: =B3*Assumptions!B2*Assumptions!B3 -> 8430010.4 | D3: =(B3+C3)*Assumptions!B4 -> 40366125 | E3: 0 | F3: =(D3-E3)*2 -> 80732251 | G3: =F3*(1+Assumptions!B5+Assumptions!B6+Assumptions!B7) -> 88805476 | H3: =G3*(1+Assumptions!B8+Assumptions!B9) -> 1.021263e+08 | I3: =H3/12 -> 8510524.8 | J3: =H3/2 -> 51063149 | K3: =H3 -> 1.021263e+08
A4: Arunachal Pradesh | B4: =SUM('Livestock Count'!B4:F4) -> 784148 | C4: =B4*Assumptions!B2*Assumptions!B3 -> 194076.63 | D4: =(B4+C4)*Assumptions!B4 -> 929313.4 | E4: 0 | F4: =(D4-E4)*2 -> 1858626.8 | G4: =F4*(1+Assumptions!B5+Assumptions!B6+Assumptions!B7) -> 2044489.5 | H4: =G4*(1+Assumptions!B8+Assumptions!B9) -> 2351162.9 | I4: =H4/12 -> 195930.24 | J4: =H4/2 -> 1175581.4 | K4: =H4 -> 2351162.9
A5: Assam | B5: =SUM('Livestock Count'!B5:F5) -> 18077227 | C5: =B5*Assumptions!B2*Assumptions!B3 -> 4474113.7 | D5: =(B5+C5)*Assumptions!B4 -> 21423774 | E5: 0 | F5: =(D5-E5)*2 -> 42847547 | G5: =F5*(1+Assumptions!B5+Assumptions!B6+Assumptions!B7) -> 47132302 | H5: =G5*(1+Assumptions!B8+Assumptions!B9) -> 54202147 | I5: =H5/12 -> 4516845.6 | J5: =H5/2 -> 27101074 | K5: =H5 -> 54202147
A6: Bihar | B6: =SUM('Livestock Count'!B6:F6) -> 36495801 | C6: =B6*Assumptions!B2*Assumptions!B3 -> 9032710.7 | D6: =(B6+C6)*Assumptions!B4 -> 43252086 | E6: 0 | F6: =(D6-E6)*2 -> 86504172 | G6: =F6*(1+Assumptions!B5+Assumptions!B6+Assumptions!B7) -> 95154590 | H6: =G6*(1+Assumptions!B8+Assumptions!B9) -> 1.0942778e+08 | I6: =H6/12 -> 9118981.5 | J6: =H6/2 -> 54713889 | K6: =H6 -> 1.0942778e+08
A7: Chandigarh | B7: =SUM('Livestock Count'!B7:F7) -> 26753 | C7: =B7*Assumptions!B2*Assumptions!B3 -> 6621.3675 | D7: =(B7+C7)*Assumptions!B4 -> 31705.649 | E7: 0 | F7: =(D7-E7)*2 -> 63411.298 | G7: =F7*(1+Assumptions!B5+Assumptions!B6+Assumptions!B7) -> 69752.428 | H7: =G7*(1+Assumptions!B8+Assumptions!B9) -> 80215.292 | I7: =H7/12 -> 6684.6077 | J7: =H7/2 -> 40107.646 | K7: =H7 -> 80215.292
A8: Chhattisgarh | B8: =SUM('Livestock Count'!B8:F8) -> 15871463 | C8: =B8*Assumptions!B2*Assumptions!B3 -> 3928187.1 | D8: =(B8+C8)*Assumptions!B4 -> 18809668 | E8: 0 | F8: =(D8-E8)*2 -> 37619335 | G8: =F8*(1+Assumptions!B5+Assumptions!B6+Assumptions!B7) -> 41381269 | H8: =G8*(1+Assumptions!B8+Assumptions!B9) -> 47588459 | I8: =H8/12 -> 3965704.9 | J8: =H8/2 -> 23794229 | K8: =H8 -> 47588459
A9: Dadra & Nagar Haveli | B9: =SUM('Livestock Count'!B9:F9) -> 48365 | C9: =B9*Assumptions!B2*Assumptions!B3 -> 11970.338 | D9: =(B9+C9)*Assumptions!B4 -> 57318.571 | E9: 0 | F9: =(D9-E9)*2 -> 114637.14 | G9: =F9*(1+Assumptions!B5+Assumptions!B6+Assumptions!B7) -> 126100.86 | H9: =G9*(1+Assumptions!B8+Assumptions!B9) -> 145015.98 | I9: =H9/12 -> 12084.665 | J9: =H9/2 -> 72507.992 | K9: =H9 -> 145015.98
A10: Daman & Diu | B10: =SUM('Livestock Count'!B10:F10) -> 3269 | C10: =B10*Assumptions!B2*Assumptions!B3 -> 809.0775 | D10: =(B10+C10)*Assumptions!B4 -> 3874.1736 | E10: 0 | F10: =(D10-E10)*2 -> 7748.3472 | G10: =F10*(1+Assumptions!B5+Assumptions!B6+Assumptions!B7) -> 8523.182 | H10: =G10*(1+Assumptions!B8+Assumptions!B9) -> 9801.6593 | I10: =H10/12 -> 816.80494 | J10: =H10/2 -> 4900.8296 | K10: =H10 -> 9801.6593
A11: Delhi | B11: =SUM('Livestock Count'!B11:F11) -> 356323 | C11: =B11*Assumptions!B2*Assumptions!B3 -> 88189.943 | D11: =(B11+C11)*Assumptions!B4 -> 422287.3 | E11: 0 | F11: =(D11-E11)*2 -> 844574.59 | G11: =F11*(1+Assumptions!B5+Assumptions!B6+Assumptions!B7) -> 929032.05 | H11: =G11*(1+Assumptions!B8+Assumptions!B9) -> 1068386.9 | I11: =H11/12 -> 89032.238 | J11: =H11/2 -> 534193.43 | K11: =H11 -> 1068386.9
A12: Goa | B12: =SUM('Livestock Count'!B12:F12) -> 132388 | C12: =B12*Assumptions!B2*Assumptions!B3 -> 32766.03 | D12: =(B12+C12)*Assumptions!B4 -> 156896.33 | E12: 0 | F12: =(D12-E12)*2 -> 313792.66 | G12: =F12*(1+Assumptions!B5+Assumptions!B6+Assumptions!B7) -> 345171.92 | H12: =G12*(1+Assumptions!B8+Assumptions!B9) -> 396947.71 | I12: =H12/12 -> 33078.976 | J12: =H12/2 -> 198473.86 | K12: =H12 -> 396947.71
A13: Gujarat | B13: =SUM('Livestock Count'!B13:F13) -> 26832552 | C13: =B13*Assumptions!B2*Assumptions!B3 -> 6641056.6 | D13: =(B13+C13)*Assumptions!B4 -> 31799928 | E13: 0 | F13: =(D13-E13)*2 -> 63599856 | G13: =F13*(1+Assumptions!B5+Assumptions!B6+Assumptions!B7) -> 69959842 | H13: =G13*(1+Assumptions!B8+Assumptions!B9) -> 80453818 | I13: =H13/12 -> 6704484.9 | J13: =H13/2 -> 40226909 | K13: =H13 -> 80453818
A14: Haryana | B14: =SUM('Livestock Count'!B14:F14) -> 7027955 | C14: =B14*Assumptions!B2*Assumptions!B3 -> 1739418.9 | D14: =(B14+C14)*Assumptions!B4 -> 8329005.2 | E14: 0 | F14: =(D14-E14)*2 -> 16658010 | G14: =F14*(1+Assumptions!B5+Assumptions!B6+Assumptions!B7) -> 18323811 | H14: =G14*(1+Assumptions!B8+Assumptions!B9) -> 21072383 | I14: =H14/12 -> 1756031.9 | J14: =H14/2 -> 10536192 | K14: =H14 -> 21072383
A15: Himachal Pradesh | B15: =SUM('Livestock Count'!B15:F15) -> 4376817 | C15: =B15*Assumptions!B2*Assumptions!B3 -> 1083262.2 | D15: =(B15+C15)*Assumptions!B4 -> 5187075.2 | E15: 0 | F15: =(D15-E15)*2 -> 10374150 | G15: =F15*(1+Assumptions!B5+Assumptions!B6+Assumptions!B7) -> 11411566 | H15: =G15*(1+Assumptions!B8+Assumptions!B9) -> 13123300 | I15: =H15/12 -> 1093608.4 | J15: =H15/2 -> 6561650.2 | K15: =H15 -> 13123300
A16: Jammu & Kashmir | B16: =SUM('Livestock Count'!B16:F16) -> 8209005 | C16: =B16*Assumptions!B2*Assumptions!B3 -> 2031728.7 | D16: =(B16+C16)*Assumptions!B4 -> 9728697.1 | E16: 0 | F16: =(D16-E16)*2 -> 19457394 | G16: =F16*(1+Assumptions!B5+Assumptions!B6+Assumptions!B7) -> 21403134 | H16: =G16*(1+Assumptions!B8+Assumptions!B9) -> 24613604 | I16: =H16/12 -> 2051133.6 | J16: =H16/2 -> 12306802 | K16: =H16 -> 24613604
A17: Jharkhand | B17: =SUM('Livestock Count'!B17:F17) -> 23612694 | C17: =B17*Assumptions!B2*Assumptions!B3 -> 5844141.8 | D17: =(B17+C17)*Assumptions!B4 -> 27983994 | E17: 0 | F17: =(D17-E17)*2 -> 55967988 | G17: =F17*(1+Assumptions!B5+Assumptions!B6+Assumptions!B7) -> 61564787 | H17: =G17*(1+Assumptions!B8+Assumptions!B9) -> 70799505 | I17: =H17/12 -> 5899958.7 | J17: =H17/2 -> 35399752 | K17: =H17 -> 70799505
A18: Karnataka | B18: =SUM('Livestock Count'!B18:F18) -> 28997520 | C18: =B18*Assumptions!B2*Assumptions!B3 -> 7176886.2 | D18: =(B18+C18)*Assumptions!B4 -> 34365686 | E18: 0 | F18: =(D18-E18)*2 -> 68731372 | G18: =F18*(1+Assumptions!B5+Assumptions!B6+Assumptions!B7) -> 75604509 | H18: =G18*(1+Assumptions!B8+Assumptions!B9) -> 86945185 | I18: =H18/12 -> 7245432.1 | J18: =H18/2 -> 43472593 | K18: =H18 -> 86945185
A19: Kerala | B19: =SUM('Livestock Count'!B19:F19) -> 2908006 | C19: =B19*Assumptions!B2*Assumptions!B3 -> 719731.48 | D19: =(B19+C19)*Assumptions!B4 -> 3446350.6 | E19: 0 | F19: =(D19-E19)*2 -> 6892701.2 | G19: =F19*(1+Assumptions!B5+Assumptions!B6+Assumptions!B7) -> 7581971.3 | H19: =G19*(1+Assumptions!B8+Assumptions!B9) -> 8719267 | I19: =H19/12 -> 726605.59 | J19: =H19/2 -> 4359633.5 | K19: =H19 -> 8719267
A20: Lakshadweep | B20: =SUM('Livestock Count'!B20:F20) -> 45697 | C20: =B20*Assumptions!B2*Assumptions!B3 -> 11310.008 | D20: =(B20+C20)*Assumptions!B4 -> 54156.657 | E20: 0 | F20: =(D20-E20)*2 -> 108313.31 | G20: =F20*(1+Assumptions!B5+Assumptions!B6+Assumptions!B7) -> 119144.65 | H20: =G20*(1+Assumptions!B8+Assumptions!B9) -> 137016.34 | I20: =H20/12 -> 11418.029 | J20: =H20/2 -> 68508.171 | K20: =H20 -> 137016.34
A21: Madhya Pradesh | B21: =SUM('Livestock Count'!B21:F21) -> 40611684 | C21: =B21*Assumptions!B2*Assumptions!B3 -> 10051392 | D21: =(B21+C21)*Assumptions!B4 -> 48129922 | E21: 0 | F21: =(D21-E21)*2 -> 96259844 | G21: =F21*(1+Assumptions!B5+Assumptions!B6+Assumptions!B7) -> 1.0588583e+08 | H21: =G21*(1+Assumptions!B8+Assumptions!B9) -> 1.217687e+08 | I21: =H21/12 -> 10147392 | J21: =H21/2 -> 60884351 | K21: =H21 -> 1.217687e+08
A22: Maharashtra | B22: =SUM('Livestock Count'!B22:F22) -> 33042208 | C22: =B22*Assumptions!B2*Assumptions!B3 -> 8177946.5 | D22: =(B22+C22)*Assumptions!B4 -> 39159147 | E22: 0 | F22: =(D22-E22)*2 -> 78318294 | G22: =F22*(1+Assumptions!B5+Assumptions!B6+Assumptions!B7) -> 86150123 | H22: =G22*(1+Assumptions!B8+Assumptions!B9) -> 99072641 | I22: =H22/12 -> 8256053.4 | J22: =H22/2 -> 49536321 | K22: =H22 -> 99072641
A23: Manipur | B23: =SUM('Livestock Count'!B23:F23) -> 540575 | C23: =B23*Assumptions!B2*Assumptions!B3 -> 133792.31 | D23: =(B23+C23)*Assumptions!B4 -> 640648.95 | E23: 0 | F23: =(D23-E23)*2 -> 1281297.9 | G23: =F23*(1+Assumptions!B5+Assumptions!B6+Assumptions!B7) -> 1409427.7 | H23: =G23*(1+Assumptions!B8+Assumptions!B9) -> 1620841.8 | I23: =H23/12 -> 135070.15 | J23: =H23/2 -> 810420.92 | K23: =H23 -> 1620841.8
A24: Meghalaya | B24: =SUM('Livestock Count'!B24:F24) -> 2038830 | C24: =B24*Assumptions!B2*Assumptions!B3 -> 504610.42 | D24: =(B24+C24)*Assumptions!B4 -> 2416268.4 | E24: 0 | F24: =(D24-E24)*2 -> 4832536.8 | G24: =F24*(1+Assumptions!B5+Assumptions!B6+Assumptions!B7) -> 5315790.5 | H24: =G24*(1+Assumptions!B8+Assumptions!B9) -> 6113159.1 | I24: =H24/12 -> 509429.92 | J24: =H24/2 -> 3056579.5 | K24: =H24 -> 6113159.1
A25: Mizoram | B25: =SUM('Livestock Count'!B25:F25) -> 355580 | C25: =B25*Assumptions!B2*Assumptions!B3 -> 88006.05 | D25: =(B25+C25)*Assumptions!B4 -> 421406.75 | E25: 0 | F25: =(D25-E25)*2 -> 842813.49 | G25: =F25*(1+Assumptions!B5+Assumptions!B6+Assumptions!B7) -> 927094.84 | H25: =G25*(1+Assumptions!B8+Assumptions!B9) -> 1066159.1 | I25: =H25/12 -> 88846.589 | J25: =H25/2 -> 533079.54 | K25: =H25 -> 1066159.1
A26: Nagaland | B26: =SUM('Livestock Count'!B26:F26) -> 530608 | C26: =B26*Assumptions!B2*Assumptions!B3 -> 131325.48 | D26: =(B26+C26)*Assumptions!B4 -> 628836.81 | E26: 0 | F26: =(D26-E26)*2 -> 1257673.6 | G26: =F26*(1+Assumptions!B5+Assumptions!B6+Assumptions!B7) -> 1383441 | H26: =G26*(1+Assumptions!B8+Assumptions!B9) -> 1590957.1 | I26: =H26/12 -> 132579.76 | J26: =H26/2 -> 795478.56 | K26: =H26 -> 1590957.1
A27: Odisha | B27: =SUM('Livestock Count'!B27:F27) -> 18170057 | C27: =B27*Assumptions!B2*Assumptions!B3 -> 4497089.1 | D27: =(B27+C27)*Assumptions!B4 -> 21533789 | E27: 0 | F27: =(D27-E27)*2 -> 43067578 | G27: =F27*(1+Assumptions!B5+Assumptions!B6+Assumptions!B7) -> 47374335 | H27: =G27*(1+Assumptions!B8+Assumptions!B9) -> 54480486 | I27: =H27/12 -> 4540040.5 | J27: =H27/2 -> 27240243 | K27: =H27 -> 54480486
A28: Puducherry | B28: =SUM('Livestock Count'!B28:F28) -> 151334 | C28: =B28*Assumptions!B2*Assumptions!B3 -> 37455.165 | D28: =(B28+C28)*Assumptions!B4 -> 179349.71 | E28: 0 | F28: =(D28-E28)*2 -> 358699.41 | G28: =F28*(1+Assumptions!B5+Assumptions!B6+Assumptions!B7) -> 394569.35 | H28: =G28*(1+Assumptions!B8+Assumptions!B9) -> 453754.76 | I28: =H28/12 -> 37812.897 | J28: =H28/2 -> 226877.38 | K28: =H28 -> 453754.76
A29: Punjab | B29: =SUM('Livestock Count'!B29:F29) -> 7033877 | C29: =B29*Assumptions!B2*Assumptions!B3 -> 1740884.6 | D29: =(B29+C29)*Assumptions!B4 -> 8336023.5 | E29: 0 | F29: =(D29-E29)*2 -> 16672047 | G29: =F29*(1+Assumptions!B5+Assumptions!B6+Assumptions!B7) -> 18339252 | H29: =G29*(1+Assumptions!B8+Assumptions!B9) -> 21090139 | I29: =H29/12 -> 1757511.6 | J29: =H29/2 -> 10545070 | K29: =H29 -> 21090139
A30: Rajasthan | B30: =SUM('Livestock Count'!B30:F30) -> 56529814 | C30: =B30*Assumptions!B2*Assumptions!B3 -> 13991129 | D30: =(B30+C30)*Assumptions!B4 -> 66994896 | E30: 0 | F30: =(D30-E30)*2 -> 1.3398979e+08 | G30: =F30*(1+Assumptions!B5+Assumptions!B6+Assumptions!B7) -> 1.4738877e+08 | H30: =G30*(1+Assumptions!B8+Assumptions!B9) -> 1.6949709e+08 | I30: =H30/12 -> 14124757 | J30: =H30/2 -> 84748543 | K30: =H30 -> 1.6949709e+08
A31: Sikkim | B31: =SUM('Livestock Count'!B31:F31) -> 268996 | C31: =B31*Assumptions!B2*Assumptions!B3 -> 66576.51 | D31: =(B31+C31)*Assumptions!B4 -> 318793.88 | E31: 0 | F31: =(D31-E31)*2 -> 637587.77 | G31: =F31*(1+Assumptions!B5+Assumptions!B6+Assumptions!B7) -> 701346.55 | H31: =G31*(1+Assumptions!B8+Assumptions!B9) -> 806548.53 | I31: =H31/12 -> 67212.377 | J31: =H31/2 -> 403274.26 | K31: =H31 -> 806548.53
A32: Tamil Nadu | B32: =SUM('Livestock Count'!B32:F32) -> 24493464 | C32: =B32*Assumptions!B2*Assumptions!B3 -> 6062132.3 | D32: =(B32+C32)*Assumptions!B4 -> 29027817 | E32: 0 | F32: =(D32-E32)*2 -> 58055633 | G32: =F32*(1+Assumptions!B5+Assumptions!B6+Assumptions!B7) -> 63861196 | H32: =G32*(1+Assumptions!B8+Assumptions!B9) -> 73440376 | I32: =H32/12 -> 6120031.3 | J32: =H32/2 -> 36720188 | K32: =H32 -> 73440376
A33: Telangana | B33: =SUM('Livestock Count'!B33:F33) -> 32634568 | C33: =B33*Assumptions!B2*Assumptions!B3 -> 8077055.6 | D33: =(B33+C33)*Assumptions!B4 -> 38676042 | E33: 0 | F33: =(D33-E33)*2 -> 77352085 | G33: =F33*(1+Assumptions!B5+Assumptions!B6+Assumptions!B7) -> 85087293 | H33: =G33*(1+Assumptions!B8+Assumptions!B9) -> 97850387 | I33: =H33/12 -> 8154198.9 | J33: =H33/2 -> 48925194 | K33: =H33 -> 97850387
A34: Tripura | B34: =SUM('Livestock Count'!B34:F34) -> 1317861 | C34: =B34*Assumptions!B2*Assumptions!B3 -> 326170.6 | D34: =(B34+C34)*Assumptions!B4 -> 1561830 | E34: 0 | F34: =(D34-E34)*2 -> 3123660 | G34: =F34*(1+Assumptions!B5+Assumptions!B6+Assumptions!B7) -> 3436026 | H34: =G34*(1+Assumptions!B8+Assumptions!B9) -> 3951429.9 | I34: =H34/12 -> 329285.83 | J34: =H34/2 -> 1975715 | K34: =H34 -> 3951429.9
A35: Uttar Pradesh | B35: =SUM('Livestock Count'!B35:F35) -> 67909854 | C35: =B35*Assumptions!B2*Assumptions!B3 -> 16807689 | D35: =(B35+C35)*Assumptions!B4 -> 80481666 | E35: 0 | F35: =(D35-E35)*2 -> 1.6096333e+08 | G35: =F35*(1+Assumptions!B5+Assumptions!B6+Assumptions!B7) -> 1.7705966e+08 | H35: =G35*(1+Assumptions!B8+Assumptions!B9) -> 2.0361861e+08 | I35: =H35/12 -> 16968218 | J35: =H35/2 -> 1.0180931e+08 | K35: =H35 -> 2.0361861e+08
A36: Uttarakhand | B36: =SUM('Livestock Count'!B36:F36) -> 4392686 | C36: =B36*Assumptions!B2*Assumptions!B3 -> 1087189.8 | D36: =(B36+C36)*Assumptions!B4 -> 5205882 | E36: 0 | F36: =(D36-E36)*2 -> 10411764 | G36: =F36*(1+Assumptions!B5+Assumptions!B6+Assumptions!B7) -> 11452940 | H36: =G36*(1+Assumptions!B8+Assumptions!B9) -> 13170881 | I36: =H36/12 -> 1097573.5 | J36: =H36/2 -> 6585440.7 | K36: =H36 -> 13170881
A37: West Bengal | B37: =SUM('Livestock Count'!B37:F37) -> 37481419 | C37: =B37*Assumptions!B2*Assumptions!B3 -> 9276651.2 | D37: =(B37+C37)*Assumptions!B4 -> 44420167 | E37: 0 | F37: =(D37-E37)*2 -> 88840333 | G37: =F37*(1+Assumptions!B5+Assumptions!B6+Assumptions!B7) -> 97724367 | H37: =G37*(1+Assumptions!B8+Assumptions!B9) -> 1.1238302e+08 | I37: =H37/12 -> 9365251.8 | J37: =H37/2 -> 56191511 | K37: =H37 -> 1.1238302e+08

Sheet Brucellosis Demand
A1: State/UT | B1: Eligible Animals | C1: New Birth Eligible | D1: Adjusted Eligible (Coverage) | E1: Current Inventory | F1: Annual Dose Requirement | G1: After Losses | H1: After Buffer & Campaign | I1: Monthly Demand | J1: Half-Yearly Demand | K1: Annual Demand
A2: Andaman & Nicobar Islands | B2: =SUM('Livestock Count'!B2:C2) -> 40138 | C2: =B2*Assumptions!B2*Assumptions!B3 -> 9934.155 | D2: =(B2+C2)*Assumptions!B4 -> 47568.547 | E2: 0 | F2: =(D2-E2)*1 -> 47568.547 | G2: =F2*(1+Assumptions!B5+Assumptions!B6+Assumptions!B7) -> 52325.402 | H2: =G2*(1+Assumptions!B8+Assumptions!B9) -> 60174.212 | I2: =H2/12 -> 5014.5177 | J2: =H2/2 -> 30087.106 | K2: =H2 -> 60174.212
A3: Andhra Pradesh | B3: =SUM('Livestock Count'!B3:C3) -> 10819586 | C3: =B3*Assumptions!B2*Assumptions!B3 -> 2677847.5 | D3: =(B3+C3)*Assumptions!B4 -> 12822562 | E3: 0 | F3: =(D3-E3)*1 -> 12822562 | G3: =F3*(1+Assumptions!B5+Assumptions!B6+Assumptions!B7) -> 14104818 | H3: =G3*(1+Assumptions!B8+Assumptions!B9) -> 16220541 | I3: =H3/12 -> 1351711.7 | J3: =H3/2 -> 8110270.4 | K3: =H3 -> 16220541
A4: Arunachal Pradesh | B4: =SUM('Livestock Count'!B4:C4) -> 345600 | C4: =B4*Assumptions!B2*Assumptions!B3 -> 85536 | D4: =(B4+C4)*Assumptions!B4 -> 409579.2 | E4: 0 | F4: =(D4-E4)*1 -> 409579.2 | G4: =F4*(1+Assumptions!B5+Assumptions!B6+Assumptions!B7) -> 450537.12 | H4: =G4*(1+Assumptions!B8+Assumptions!B9) -> 518117.69 | I4: =H4/12 -> 43176.474 | J4: =H4/2 -> 259058.84 | K4: =H4 -> 518117.69
A5: Assam | B5: =SUM('Livestock Count'!B5:C5) -> 11330954 | C5: =B5*Assumptions!B2*Assumptions!B3 -> 2804411.1 | D5: =(B5+C5)*Assumptions!B4 -> 13428597 | E5: 0 | F5: =(D5-E5)*1 -> 13428597 | G5: =F5*(1+Assumptions!B5+Assumptions!B6+Assumptions!B7) -> 14771457 | H5: =G5*(1+Assumptions!B8+Assumptions!B9) -> 16987175 | I5: =H5/12 -> 1415597.9 | J5: =H5/2 -> 8493587.5 | K5: =H5 -> 16987175
A6: Bihar | B6: =SUM('Livestock Count'!B6:C6) -> 23117774 | C6: =B6*Assumptions!B2*Assumptions!B3 -> 5721649.1 | D6: =(B6+C6)*Assumptions!B4 -> 27397452 | E6: 0 | F6: =(D6-E6)*1 -> 27397452 | G6: =F6*(1+Assumptions!B5+Assumptions!B6+Assumptions!B7) -> 30137197 | H6: =G6*(1+Assumptions!B8+Assumptions!B9) -> 34657777 | I6: =H6/12 -> 2888148.1 | J6: =H6/2 -> 17328888 | K6: =H6 -> 34657777
A7: Chandigarh | B7: =SUM('Livestock Count'!B7:C7) -> 25617 | C7: =B7*Assumptions!B2*Assumptions!B3 -> 6340.2075 | D7: =(B7+C7)*Assumptions!B4 -> 30359.347 | E7: 0 | F7: =(D7-E7)*1 -> 30359.347 | G7: =F7*(1+Assumptions!B5+Assumptions!B6+Assumptions!B7) -> 33395.282 | H7: =G7*(1+Assumptions!B8+Assumptions!B9) -> 38404.574 | I7: =H7/12 -> 3200.3812 | J7: =H7/2 -> 19202.287 | K7: =H7 -> 38404.574
A8: Chhattisgarh | B8: =SUM('Livestock Count'!B8:C8) -> 11158676 | C8: =B8*Assumptions!B2*Assumptions!B3 -> 2761772.3 | D8: =(B8+C8)*Assumptions!B4 -> 13224426 | E8: 0 | F8: =(D8-E8)*1 -> 13224426 | G8: =F8*(1+Assumptions!B5+Assumptions!B6+Assumptions!B7) -> 14546868 | H8: =G8*(1+Assumptions!B8+Assumptions!B9) -> 16728899 | I8: =H8/12 -> 1394074.9 | J8: =H8/2 -> 8364449.4 | K8: =H8 -> 16728899
A9: Dadra & Nagar Haveli | B9: =SUM('Livestock Count'!B9:C9) -> 40733 | C9: =B9*Assumptions!B2*Assumptions!B3 -> 10081.418 | D9: =(B9+C9)*Assumptions!B4 -> 48273.697 | E9: 0 | F9: =(D9-E9)*1 -> 48273.697 | G9: =F9*(1+Assumptions!B5+Assumptions!B6+Assumptions!B7) -> 53101.066 | H9: =G9*(1+Assumptions!B8+Assumptions!B9) -> 61066.226 | I9: =H9/12 -> 5088.8522 | J9: =H9/2 -> 30533.113 | K9: =H9 -> 61066.226
A10: Daman & Diu | B10: =SUM('Livestock Count'!B10:C10) -> 2214 | C10: =B10*Assumptions!B2*Assumptions!B3 -> 547.965 | D10: =(B10+C10)*Assumptions!B4 -> 2623.8668 | E10: 0 | F10: =(D10-E10)*1 -> 2623.8668 | G10: =F10*(1+Assumptions!B5+Assumptions!B6+Assumptions!B7) -> 2886.2534 | H10: =G10*(1+Assumptions!B8+Assumptions!B9) -> 3319.1914 | I10: =H10/12 -> 276.59929 | J10: =H10/2 -> 1659.5957 | K10: =H10 -> 3319.1914
A11: Delhi | B11: =SUM('Livestock Count'!B11:C11) -> 248575 | C11: =B11*Assumptions!B2*Assumptions!B3 -> 61522.312 | D11: =(B11+C11)*Assumptions!B4 -> 294592.45 | E11: 0 | F11: =(D11-E11)*1 -> 294592.45 | G11: =F11*(1+Assumptions!B5+Assumptions!B6+Assumptions!B7) -> 324051.69 | H11: =G11*(1+Assumptions!B8+Assumptions!B9) -> 372659.45 | I11: =H11/12 -> 31054.954 | J11: =H11/2 -> 186329.72 | K11: =H11 -> 372659.45
A12: Goa | B12: =SUM('Livestock Count'!B12:C12) -> 87454 | C12: =B12*Assumptions!B2*Assumptions!B3 -> 21644.865 | D12: =(B12+C12)*Assumptions!B4 -> 103643.92 | E12: 0 | F12: =(D12-E12)*1 -> 103643.92 | G12: =F12*(1+Assumptions!B5+Assumptions!B6+Assumptions!B7) -> 114008.31 | H12: =G12*(1+Assumptions!B8+Assumptions!B9) -> 131109.56 | I12: =H12/12 -> 10925.797 | J12: =H12/2 -> 65554.781 | K12: =H12 -> 131109.56
A13: Gujarat | B13: =SUM('Livestock Count'!B13:C13) -> 20176887 | C13: =B13*Assumptions!B2*Assumptions!B3 -> 4993779.5 | D13: =(B13+C13)*Assumptions!B4 -> 23912133 | E13: 0 | F13: =(D13-E13)*1 -> 23912133 | G13: =F13*(1+Assumptions!B5+Assumptions!B6+Assumptions!B7) -> 26303347 | H13: =G13*(1+Assumptions!B8+Assumptions!B9) -> 30248849 | I13: =H13/12 -> 2520737.4 | J13: =H13/2 -> 15124424 | K13: =H13 -> 30248849
A14: Haryana | B14: =SUM('Livestock Count'!B14:C14) -> 6296705 | C14: =B14*Assumptions!B2*Assumptions!B3 -> 1558434.5 | D14: =(B14+C14)*Assumptions!B4 -> 7462382.5 | E14: 0 | F14: =(D14-E14)*1 -> 7462382.5 | G14: =F14*(1+Assumptions!B5+Assumptions!B6+Assumptions!B7) -> 8208620.8 | H14: =G14*(1+Assumptions!B8+Assumptions!B9) -> 9439913.9 | I14: =H14/12 -> 786659.49 | J14: =H14/2 -> 4719956.9 | K14: =H14 -> 9439913.9
A15: Himachal Pradesh | B15: =SUM('Livestock Count'!B15:C15) -> 2474582 | C15: =B15*Assumptions!B2*Assumptions!B3 -> 612459.05 | D15: =(B15+C15)*Assumptions!B4 -> 2932689 | E15: 0 | F15: =(D15-E15)*1 -> 2932689 | G15: =F15*(1+Assumptions!B5+Assumptions!B6+Assumptions!B7) -> 3225957.9 | H15: =G15*(1+Assumptions!B8+Assumptions!B9) -> 3709851.6 | I15: =H15/12 -> 309154.3 | J15: =H15/2 -> 1854925.8 | K15: =H15 -> 3709851.6
A16: Jammu & Kashmir | B16: =SUM('Livestock Count'!B16:C16) -> 3230069 | C16: =B16*Assumptions!B2*Assumptions!B3 -> 799442.08 | D16: =(B16+C16)*Assumptions!B4 -> 3828035.5 | E16: 0 | F16: =(D16-E16)*1 -> 3828035.5 | G16: =F16*(1+Assumptions!B5+Assumptions!B6+Assumptions!B7) -> 4210839.1 | H16: =G16*(1+Assumptions!B8+Assumptions!B9) -> 4842464.9 | I16: =H16/12 -> 403538.74 | J16: =H16/2 -> 2421232.5 | K16: =H16 -> 4842464.9
A17: Jharkhand | B17: =SUM('Livestock Count'!B17:C17) -> 12573365 | C17: =B17*Assumptions!B2*Assumptions!B3 -> 3111907.8 | D17: =(B17+C17)*Assumptions!B4 -> 14901009 | E17: 0 | F17: =(D17-E17)*1 -> 14901009 | G17: =F17*(1+Assumptions!B5+Assumptions!B6+Assumptions!B7) -> 16391110 | H17: =G17*(1+Assumptions!B8+Assumptions!B9) -> 18849777 | I17: =H17/12 -> 1570814.7 | J17: =H17/2 -> 9424888.3 | K17: =H17 -> 18849777
A18: Karnataka | B18: =SUM('Livestock Count'!B18:C18) -> 11453564 | C18: =B18*Assumptions!B2*Assumptions!B3 -> 2834757.1 | D18: =(B18+C18)*Assumptions!B4 -> 13573905 | E18: 0 | F18: =(D18-E18)*1 -> 13573905 | G18: =F18*(1+Assumptions!B5+Assumptions!B6+Assumptions!B7) -> 14931296 | H18: =G18*(1+Assumptions!B8+Assumptions!B9) -> 17170990 | I18: =H18/12 -> 1430915.8 | J18: =H18/2 -> 8585494.9 | K18: =H18 -> 17170990
A19: Kerala | B19: =SUM('Livestock Count'!B19:C19) -> 1443500 | C19: =B19*Assumptions!B2*Assumptions!B3 -> 357266.25 | D19: =(B19+C19)*Assumptions!B4 -> 1710727.9 | E19: 0 | F19: =(D19-E19)*1 -> 1710727.9 | G19: =F19*(1+Assumptions!B5+Assumptions!B6+Assumptions!B7) -> 1881800.7 | H19: =G19*(1+Assumptions!B8+Assumptions!B9) -> 2164070.8 | I19: =H19/12 -> 180339.24 | J19: =H19/2 -> 1082035.4 | K19: =H19 -> 2164070.8
A20: Lakshadweep | B20: =SUM('Livestock Count'!B20:C20) -> 2509 | C20: =B20*Assumptions!B2*Assumptions!B3 -> 620.9775 | D20: =(B20+C20)*Assumptions!B4 -> 2973.4786 | E20: 0 | F20: =(D20-E20)*1 -> 2973.4786 | G20: =F20*(1+Assumptions!B5+Assumptions!B6+Assumptions!B7) -> 3270.8265 | H20: =G20*(1+Assumptions!B8+Assumptions!B9) -> 3761.4505 | I20: =H20/12 -> 313.45421 | J20: =H20/2 -> 1880.7252 | K20: =H20 -> 3761.4505
A21: Madhya Pradesh | B21: =SUM('Livestock Count'!B21:C21) -> 29057959 | C21: =B21*Assumptions!B2*Assumptions!B3 -> 7191844.9 | D21: =(B21+C21)*Assumptions!B4 -> 34437314 | E21: 0 | F21: =(D21-E21)*1 -> 34437314 | G21: =F21*(1+Assumptions!B5+Assumptions!B6+Assumptions!B7) -> 37881045 | H21: =G21*(1+Assumptions!B8+Assumptions!B9) -> 43563202 | I21: =H21/12 -> 3630266.8 | J21: =H21/2 -> 21781601 | K21: =H21 -> 43563202
A22: Maharashtra | B22: =SUM('Livestock Count'!B22:C22) -> 19595996 | C22: =B22*Assumptions!B2*Assumptions!B3 -> 4850009 | D22: =(B22+C22)*Assumptions!B4 -> 23223705 | E22: 0 | F22: =(D22-E22)*1 -> 23223705 | G22: =F22*(1+Assumptions!B5+Assumptions!B6+Assumptions!B7) -> 25546075 | H22: =G22*(1+Assumptions!B8+Assumptions!B9) -> 29377987 | I22: =H22/12 -> 2448165.5 | J22: =H22/2 -> 14688993 | K22: =H22 -> 29377987
A23: Manipur | B23: =SUM('Livestock Count'!B23:C23) -> 260702 | C23: =B23*Assumptions!B2*Assumptions!B3 -> 64523.745 | D23: =(B23+C23)*Assumptions!B4 -> 308964.46 | E23: 0 | F23: =(D23-E23)*1 -> 308964.46 | G23: =F23*(1+Assumptions!B5+Assumptions!B6+Assumptions!B7) -> 339860.9 | H23: =G23*(1+Assumptions!B8+Assumptions!B9) -> 390840.04 | I23: =H23/12 -> 32570.003 | J23: =H23/2 -> 195420.02 | K23: =H23 -> 390840.04
A24: Meghalaya | B24: =SUM('Livestock Count'!B24:C24) -> 919284 | C24: =B24*Assumptions!B2*Assumptions!B3 -> 227522.79 | D24: =(B24+C24)*Assumptions!B4 -> 1089466.5 | E24: 0 | F24: =(D24-E24)*1 -> 1089466.5 | G24: =F24*(1+Assumptions!B5+Assumptions!B6+Assumptions!B7) -> 1198413.1 | H24: =G24*(1+Assumptions!B8+Assumptions!B9) -> 1378175.1 | I24: =H24/12 -> 114847.92 | J24: =H24/2 -> 689087.53 | K24: =H24 -> 1378175.1
A25: Mizoram | B25: =SUM('Livestock Count'!B25:C25) -> 47810 | C25: =B25*Assumptions!B2*Assumptions!B3 -> 11832.975 | D25: =(B25+C25)*Assumptions!B4 -> 56660.826 | E25: 0 | F25: =(D25-E25)*1 -> 56660.826 | G25: =F25*(1+Assumptions!B5+Assumptions!B6+Assumptions!B7) -> 62326.909 | H25: =G25*(1+Assumptions!B8+Assumptions!B9) -> 71675.945 | I25: =H25/12 -> 5972.9954 | J25: =H25/2 -> 35837.973 | K25: =H25 -> 71675.945
A26: Nagaland | B26: =SUM('Livestock Count'!B26:C26) -> 93950 | C26: =B26*Assumptions!B2*Assumptions!B3 -> 23252.625 | D26: =(B26+C26)*Assumptions!B4 -> 111342.49 | E26: 0 | F26: =(D26-E26)*1 -> 111342.49 | G26: =F26*(1+Assumptions!B5+Assumptions!B6+Assumptions!B7) -> 122476.74 | H26: =G26*(1+Assumptions!B8+Assumptions!B9) -> 140848.25 | I26: =H26/12 -> 11737.355 | J26: =H26/2 -> 70424.127 | K26: =H26 -> 140848.25
A27: Odisha | B27: =SUM('Livestock Count'!B27:C27) -> 10362294 | C27: =B27*Assumptions!B2*Assumptions!B3 -> 2564667.8 | D27: =(B27+C27)*Assumptions!B4 -> 12280614 | E27: 0 | F27: =(D27-E27)*1 -> 12280614 | G27: =F27*(1+Assumptions!B5+Assumptions!B6+Assumptions!B7) -> 13508675 | H27: =G27*(1+Assumptions!B8+Assumptions!B9) -> 15534976 | I27: =H27/12 -> 1294581.4 | J27: =H27/2 -> 7767488.2 | K27: =H27 -> 15534976
A28: Puducherry | B28: =SUM('Livestock Count'!B28:C28) -> 74379 | C28: =B28*Assumptions!B2*Assumptions!B3 -> 18408.803 | D28: =(B28+C28)*Assumptions!B4 -> 88148.412 | E28: 0 | F28: =(D28-E28)*1 -> 88148.412 | G28: =F28*(1+Assumptions!B5+Assumptions!B6+Assumptions!B7) -> 96963.254 | H28: =G28*(1+Assumptions!B8+Assumptions!B9) -> 111507.74 | I28: =H28/12 -> 9292.3118 | J28: =H28/2 -> 55753.871 | K28: =H28 -> 111507.74
A29: Punjab | B29: =SUM('Livestock Count'!B29:C29) -> 6547407 | C29: =B29*Assumptions!B2*Assumptions!B3 -> 1620483.2 | D29: =(B29+C29)*Assumptions!B4 -> 7759495.7 | E29: 0 | F29: =(D29-E29)*1 -> 7759495.7 | G29: =F29*(1+Assumptions!B5+Assumptions!B6+Assumptions!B7) -> 8535445.3 | H29: =G29*(1+Assumptions!B8+Assumptions!B9) -> 9815762.1 | I29: =H29/12 -> 817980.17 | J29: =H29/2 -> 4907881 | K29: =H29 -> 9815762.1
A30: Rajasthan | B30: =SUM('Livestock Count'!B30:C30) -> 27630946 | C30: =B30*Assumptions!B2*Assumptions!B3 -> 6838659.1 | D30: =(B30+C30)*Assumptions!B4 -> 32746125 | E30: 0 | F30: =(D30-E30)*1 -> 32746125 | G30: =F30*(1+Assumptions!B5+Assumptions!B6+Assumptions!B7) -> 36020737 | H30: =G30*(1+Assumptions!B8+Assumptions!B9) -> 41423848 | I30: =H30/12 -> 3451987.3 | J30: =H30/2 -> 20711924 | K30: =H30 -> 41423848
A31: Sikkim | B31: =SUM('Livestock Count'!B31:C31) -> 149154 | C31: =B31*Assumptions!B2*Assumptions!B3 -> 36915.615 | D31: =(B31+C31)*Assumptions!B4 -> 176766.13 | E31: 0 | F31: =(D31-E31)*1 -> 176766.13 | G31: =F31*(1+Assumptions!B5+Assumptions!B6+Assumptions!B7) -> 194442.75 | H31: =G31*(1+Assumptions!B8+Assumptions!B9) -> 223609.16 | I31: =H31/12 -> 18634.097 | J31: =H31/2 -> 111804.58 | K31: =H31 -> 223609.16
A32: Tamil Nadu | B32: =SUM('Livestock Count'!B32:C32) -> 10037455 | C32: =B32*Assumptions!B2*Assumptions!B3 -> 2484270.1 | D32: =(B32+C32)*Assumptions!B4 -> 11895639 | E32: 0 | F32: =(D32-E32)*1 -> 11895639 | G32: =F32*(1+Assumptions!B5+Assumptions!B6+Assumptions!B7) -> 13085203 | H32: =G32*(1+Assumptions!B8+Assumptions!B9) -> 15047983 | I32: =H32/12 -> 1253998.6 | J32: =H32/2 -> 7523991.6 | K32: =H32 -> 15047983
A33: Telangana | B33: =SUM('Livestock Count'!B33:C33) -> 8458845 | C33: =B33*Assumptions!B2*Assumptions!B3 -> 2093564.1 | D33: =(B33+C33)*Assumptions!B4 -> 10024789 | E33: 0 | F33: =(D33-E33)*1 -> 10024789 | G33: =F33*(1+Assumptions!B5+Assumptions!B6+Assumptions!B7) -> 11027268 | H33: =G33*(1+Assumptions!B8+Assumptions!B9) -> 12681358 | I33: =H33/12 -> 1056779.8 | J33: =H33/2 -> 6340678.8 | K33: =H33 -> 12681358
A34: Tripura | B34: =SUM('Livestock Count'!B34:C34) -> 746162 | C34: =B34*Assumptions!B2*Assumptions!B3 -> 184675.1 | D34: =(B34+C34)*Assumptions!B4 -> 884295.24 | E34: 0 | F34: =(D34-E34)*1 -> 884295.24 | G34: =F34*(1+Assumptions!B5+Assumptions!B6+Assumptions!B7) -> 972724.76 | H34: =G34*(1+Assumptions!B8+Assumptions!B9) -> 1118633.5 | I34: =H34/12 -> 93219.457 | J34: =H34/2 -> 559316.74 | K34: =H34 -> 1118633.5
A35: Uttar Pradesh | B35: =SUM('Livestock Count'!B35:C35) -> 52036426 | C35: =B35*Assumptions!B2*Assumptions!B3 -> 12879015 | D35: =(B35+C35)*Assumptions!B4 -> 61669669 | E35: 0 | F35: =(D35-E35)*1 -> 61669669 | G35: =F35*(1+Assumptions!B5+Assumptions!B6+Assumptions!B7) -> 67836636 | H35: =G35*(1+Assumptions!B8+Assumptions!B9) -> 78012132 | I35: =H35/12 -> 6501011 | J35: =H35/2 -> 39006066 | K35: =H35 -> 78012132
